Workbook
Name Price: 封面!$B$9
Name Ticker: 封面!$B$5

Sheet 使用说明
A1: 个股分析工具箱 · 固定模板（Windows 可直接打开）
A2: 用法：复制本文件并改名为「代码-日期.xlsx」，只改黄色格子（蓝字）。黑字/绿底是公式，绿字引用其他表。不要在母版上填数。打开后若公式显示 0，按 F9 或启用编辑。仅供研究，不构成投资建议。
A4: 每次怎么用（不用安装、不用联网配置）
A5: 步 | B5: 动作 | C5: 说明
A6: 1 | B6: 复制本文件 | C6: 在 Windows 上用 Excel 或 WPS 打开。每分析一只股票，先复制一份，改成例如 0992.HK-20260826.xlsx。
A7: 2 | B7: 只填封面 | C7: 在「封面」填代码、市场、现价、一句话论点。其余表会自动带上代码。
A8: 3 | B8: 按顺序往右填 | C8: 初筛 → 财务 → 评分 → 估值 → 情绪 → 风险 → 备忘录。初筛不过关就停，不要建模型。
A9: 4 | B9: 看封面结论 | C9: 封面会汇总：初筛闸门、F/Z/M 分数、估值区间、建议仓位。备忘录用于写成文。
A11: 四层分析顺序（不要打乱）
A12: 层 | B12: 要回答的问题 | C12: 产出 | D12: 停手条件 | E12: 大约耗时 | F12: 对应工作表
A13: 1 初筛 | B13: 这家公司靠什么赚钱？两句话能否说清？ | C13: 通过 / 排除 / 待完成 | D13: 说不清模式，或经营现金流连续为负 | E13: 15 分钟 | F13: 初筛
A14: 2 基本面 | B14: 增长有没有现金？护城河有没有回报率？ | C14: 质量评级 + 估值区间 | D14: 关键数字对不上年报 | E14: 1–2 小时 | F14: 财务 / 评分 / 估值
A15: 3 情绪 | B15: 现价已经定价了什么？拥挤还是冷清？ | C15: 预期差方向 | D15: 只有热度没有分歧点 | E15: 30–60 分钟 | F15: 情绪
A16: 4 风险 | B16: 什么信号出现就认错？亏多少能睡得着？ | C16: 证伪条件 + 仓位上限 | D16: 找不到可观察的证伪条件 | E16: 20–40 分钟 | F16: 风险 / 备忘录
A18: 格子颜色
A19: 颜色 | B19: 含义 | C19: 你要做什么
B20: 黄底蓝字 | C20: 输入：价格、财务数字、是/否、情景假设、文字判断
B21: 绿底黑/绿字 | C21: 公式或跨表引用：不要改。改输入后这里会变。
B22: 浅蓝底 | C22: 说明和提示，不用填。
A24: 原则
A25: · 先质量、再估值、再读预期差、最后用风险定仓位。不要把基本面、情绪、技术面合成一个分数。
A26: · 事实带来源（年报页码、交易所公告、数据商），判断写假设。结论必须可证伪。
A27: · 估值给 Bull / Base / Bear 区间，不给神预测。情绪只修正时机和仓位，不单独产生买点。
A28: · 仓位由波动和流动性决定，不由信念强度决定。初筛排除的票，后面表可以不填。

Sheet 封面
A1: 封面结论 · 每只股票从这里开始
A2: 黄色格子必填。下面「自动汇总」会从其他表取数，请先填初筛/评分/估值/风险。决策三分法允许三者不一致。
A4: 标的
A5: 股票代码 | B5: 00659 | D5: 例如 0992.HK / 600519 / NVDA
A6: 公司名称 | B6: 周大福创建
A7: 市场 | B7: 港股 | D7: A股 / 港股 / 美股
A8: 分析日期 | B8: 46290 | D8: YYYY-MM-DD
A9: 现价 | B9: 8.4 | D9: 用交易货币
A10: 货币 | B10: HKD | D10: CNY / HKD / USD
A11: 行业 | B11: 收费公路、保险、物流、建筑与设施管理
A12: 报告期 | B12: FY2026（截至2026-06-30） | D12: 例如 FY2025 或 2026H1
A13: 一句话投资论点 | B13: 主业应占溢利仍增长且经营现金方向为正，但现价已靠近牛市情景，普通股息相对股东应占溢利的派息比例高于1。
A16: 决策三分法（人工判断，允许不一致）
A17: 内在价值 | B17: 贵 | D17: 便宜 / 合理 / 贵
A18: 近 1–3 月方向 | B18: 中性 | D18: 偏多 / 中性 / 偏空
A19: 投资动作 | B19: 等待 | D19: 买入 / 等待 / 减仓 / 观察 / 排除
A20: 财报可信度 | B20: B | D20: A / B / C / D
A21: 研究置信度 | B21: 中 | D21: 高 / 中 / 低
A22: 最大风险（一条） | B22: 普通股息金额高于本年股东应占溢利，而业绩公告没有给出经营现金流金额；若现金覆盖不了每股0.61港元的普通股息，高股息叙事就不成立。 | D22: 会推翻论点的那一条
A24: 自动汇总（不要改公式）
A25: 项目 | B25: 结果 | C25: 读法
A26: 初筛闸门 | B26: =初筛!B12 | C26: 通过才继续；排除则停。
A27: 初筛通过项 | B27: =初筛!B11 | C27: 5 项里有几项为「是」。
A28: Piotroski F | B28: =评分!B65 | C28: 8–9 强，0–3 弱。不判断贵贱。
A29: Altman Z | B29: =评分!B66 | C29: >2.99 较安全，<1.81 困境区。金融股勿套。
A30: Beneish M | B30: =评分!B67 | C30: M > -1.78 需警惕盈余操纵。
A31: Base 隐含价 | B31: =估值!C28 | C31: 基准情景价格。
A32: 估值区间 | B32: =估值!C31 | C32: Bear ~ Bull。
A33: 期望价 vs 现价 | B33: =估值!C30 | C33: 正数=模型比现价高。
A34: 建议仓位上限 | B34: =风险!C16 | C34: 占组合权益比例。
A35: 建议金额 | B35: =风险!C15 | C35: 再与流动性上限取小。
A37: 填写进度 | B37: =COUNTA(B5:B12)+COUNTA(B17:B22)&" 项已填" | C37: 本模板不抓行情。现价、财务请自己从年报 / 交易所 / 数据终端填入。

Sheet 初筛
A1: 15 分钟初筛 · 过不了就停
A2: ="标的："&IF(封面!B5="","（先填封面代码）",封面!B5&" "&封面!B6)
A3: 只回答能不能研究，不回答贵不贵。任一项为「否」→ 排除。五项皆「是」→ 通过。有「待查」→ 先去补材料。
A5: # | B5: 检查项 | C5: 结论 | D5: 备注（来源/页码） | E5: 健康信号 | F5: 危险信号
A6: 1 | B6: 商业模式：能用两句话讲清客户、收费方式、成本从哪来 | C6: 是 | D6: 客户来自道路使用者、保单持有人、物流租户、建造业主和会展医疗场馆。FY2026对外收入27,099.7百万港元，其中建筑17,915.8、金融4,752.4、道路2,777.8。港交所2026-09-24全年业绩公告。 | E6: 模式一句话说清 | F6: 说不清怎么赚钱
A7: 2 | B7: 大股东/实控人：是经营公司，还是把公司当融资工具 | C7: 是 | D7: 主席郑家纯，执行董事包括郑志明、郑志亮。公司经营道路、保险、物流和建筑，并连续第23年派发普通股息。年内有可换股债券转换和红股，但不是把上市公司只当作融资壳。公告董事会一节及股息一节。 | E7: 利益与小股东同向 | F7: 频繁定增、占用、担保
A8: 3 | B8: 最近完整年度经营现金流为正，且与净利润方向一致 | C8: 是 | D8: 股东应占溢利2,392.6百万港元，方向为正。财务资源一节写明债务净额下降的原因包括经营活动产生的净现金流入。公告没有现金流量表，金额待查，方向足够判断本项。 | E8: OCF>0 且与利润同向 | F8: 利润涨、现金持续为负
A9: 4 | B9: 有息负债、短债、财务费用在可承受范围 | C9: 是 | D9: 借貸及其他計息負債32,415.2百万港元，现金及银行結存20,760.7百万，债务净额11,654.5百万。一年内到期债务约79亿港元，可用流动资金约313亿港元。平均借贷成本约4.1%。财务费用1,494.2百万，低于经营溢利3,731.5百万。 | E9: 短债有现金或稳定现金流覆盖 | F9: 短债滚续、利息吃掉利润
A10: 5 | B10: 扣除非经常性损益后，主业利润还站得住 | C10: 是 | D10: 股东应占溢利2,392.6百万港元。非经营项目合计为净亏损，包括投资物业公平值亏损和道路减值，不是靠一次性收益撑起利润。应占经营溢利4,590.6百万港元。香港公告没有A股扣非口径。 | E10: 扣非后主业仍赚钱 | F10: 靠补贴、公允价值、一次性项目
A11: 通过项数 | B11: =COUNTIF(C6:C10,"是") | C11: =COUNTIF(C6:C10,"是")&" / 5"
A12: 闸门结论 | B12: =IF(COUNTIF(C6:C10,"否")>0,"排除",IF(COUNTIF(C6:C10,"是")=5,"通过","待完成")) | C12: 排除：停止建模。通过：进入财务表。待完成：先补年报/公告。
A14: 若通过，用一句话写下商业模式（给备忘录用）
A15: 向道路使用者、投保人、租户和建造业主收费；成本主要是建筑成本、保险服务费用和特许经营摊销。FY2026收入27,099.7百万港元，经营溢利3,731.5百万港元。

Sheet 财务
A1: 财务质量 · 先核对三表，再谈估值
A2: ="标的："&IF(封面!B5="","（先填封面）",封面!B5&" "&封面!B6&" 报告期 "&封面!B12)
A3: 黄格填年报数字（单位自定，全表保持一致，建议百万元）。绿格是同比或比率。至少填最近两年，才能驱动「评分」表。金融股部分比率不适用，在备注说明。
A5: 科目 | B5: T-4 | C5: T-3 | D5: T-2 | E5: T-1 | F5: T（最新） | G5: T 同比 | H5: 现金转化/备注 | I5: 来源（年报页）
A6: 年份（文本） | E6: FY2025 | F6: FY2026 | G6: 勿填 | H6: 单位写这里 → | I6: 百万港元
A7: 营业收入 | E7: 24285.3 | F7: 27099.7 | G7: =IF(OR(E7="",E7=0,F7=""),"",(F7-E7)/E7) | H7: 对外收入 | I7: 港交所业绩公告综合收益表收入。更早年度待查。
A8: 毛利 | E8: 3951.5 | F8: 4019.2 | G8: =IF(OR(E8="",E8=0,F8=""),"",(F8-E8)/E8) | H8: 自算毛利 | I8: 收入减销售成本减保险服务费用。未扣保险财务开支。
A9: 毛利率 | E9: 0.1627116 | F9: 0.1483116 | G9: =IF(OR(E9="",F9=""),"",F9-E9) | H9: =IF(OR(F7="",F7=0,F8=""),"",F8/F7) | I9: 毛利除以收入。
A10: 扣非净利润 | E10: 2162 | F10: 2392.6 | G10: =IF(OR(E10="",E10=0,F10=""),"",(F10-E10)/E10) | H10: 股东应占溢利 | I10: 香港公告无A股扣非。非经营项目为净亏损，这里用股东应占溢利，不把一次性收益加回。
A11: 净利润 | E11: 2162 | F11: 2392.6 | G11: =IF(OR(E11="",E11=0,F11=""),"",(F11-E11)/E11) | H11: 股东应占 | I11: 综合收益表本公司股东应占溢利。年内溢利含永续资本证券持有者，FY2026为2,570.9。
A12: 经营现金流 | G12: =IF(OR(E12="",E12=0,F12=""),"",(F12-E12)/E12) | H12: =IF(OR(F11="",F11=0,F12=""),"",F12/F11) | I12: 现金流量表未载于这份业绩公告。正文只写经营活动产生净现金流入，金额待查。 金额待查
A13: 资本开支 | G13: =IF(OR(E13="",E13=0,F13=""),"",(F13-E13)/E13) | H13: 待查 | I13: 现金资本开支待查。分部附注的资产增加FY2026为1,832.9百万港元，不是资本开支。
A14: 自由现金流 | G14: =IF(OR(E14="",E14=0,F14=""),"",(F14-E14)/E14) | H14: =IF(OR(F12="",F13=""),"",F12-F13) | I14: 经营现金流金额待查，自由现金流待查。 待查
A15: ROE | E15: 0.057627516 | F15: 0.060239993 | G15: =IF(OR(E15="",F15=""),"",F15-E15) | H15: 期末ROE | I15: 股东应占溢利除以期末股东权益，不是平均权益。
A16: ROIC | E16: 0.048332327 | F16: 0.057053244 | G16: =IF(OR(E16="",F16=""),"",F16-E16) | H16: 近似ROIC | I16: 经营溢利×（1-实际税率）除以（期末股东权益+债务净额）。实际税率=所得税/除税前溢利。保险浮存金使这个口径只是近似。
A17: 总资产 | E17: 172895.6 | F17: 191157.6 | G17: =IF(OR(E17="",E17=0,F17=""),"",(F17-E17)/E17) | I17: 综合财务状况表总资产。
A18: 有息负债 | E18: 34861.8 | F18: 32415.2 | G18: =IF(OR(E18="",E18=0,F18=""),"",(F18-E18)/E18) | I18: 借貸及其他計息負債。租赁负债另计，FY2026为550.1，未并入本行。
A19: 现金及等价物 | E19: 20210.7 | F19: 20760.7 | G19: =IF(OR(E19="",E19=0,F19=""),"",(F19-E19)/E19) | I19: 现金及银行结存。待售资产里另有现金424.2，未并入本行。
A20: 净负债 | E20: 14651.1 | F20: 11654.5 | G20: =IF(OR(E20="",E20=0,F20=""),"",(F20-E20)/E20) | H20: =IF(OR(F18="",F19=""),"",F18-F19) | I20: 有息负债减现金。FY2026等于公告债务净额116.545亿港元。
A21: 商誉 | G21: =IF(OR(E21="",E21=0,F21=""),"",(F21-E21)/E21) | H21: 待查 | I21: 资产负债表未单列商誉。无形资产FY2026为6,177.4，特许经营权6,178.4。商誉待查。
A22: 应收账款 | E22: 1853.2 | F22: 1659.6 | G22: =IF(OR(E22="",E22=0,F22=""),"",(F22-E22)/E22) | H22: 贸易应收 | I22: 附注10贸易应收款账龄合计。贸易及其他应收款FY2026为8,784.8，口径更宽。
A23: 存货 | E23: 20.8 | F23: 28 | G23: =IF(OR(E23="",E23=0,F23=""),"",(F23-E23)/E23) | I23: 存货。
A24: 股本（稀释后） | E24: 4009.8 | F24: 4566.3 | G24: =IF(OR(E24="",E24=0,F24=""),"",(F24-E24)/E24) | H24: 百万股 | I24: 股本。末期股息1,506.9百万港元除以0.33港元等于4,566.4百万股，与FY2026股本4,566.3一致，按每股面值1港元理解。
A25: 核对：H9 应接近你填的毛利率；H12 是经营现金流/净利润（现金转化，>0.8 较健康）；H14=OCF-资本开支；H20=有息负债-现金。数字对不上年报时先停。
A27: 质量解读（文字，给备忘录用）
A28: 维度 | B28: 看什么 | C28: 你的判断（黄格） | F28: 危险信号对照
A29: 成长 | B29: 营收、扣非净利、FCF 是否同向 | C29: 收入从24,285.3升至27,099.7，股东应占溢利从2,162.0升至2,392.6。自由现金流金额待查，不能说三者同向增长已经核对完成。 | F29: 利润涨、现金不涨
A30: 盈利 | B30: 毛利率稳或升，费用不失控 | C30: 按收入减销售成本和保险服务费用，毛利率从0.163降到0.148。建筑应占经营溢利降4%，物流降13%，不是靠压缩费用做出的增长。 | F30: 靠费用压缩撑净利
A31: 回报 | B31: ROIC 是否持续高于资本成本 | C31: 近似ROIC为0.057，期末ROE为0.060。债务净额下降，不是靠加杠杆抬ROE。保险浮存金使ROIC和资本成本不宜直接对比，完整周期是否高于WACC待查。 | F31: 靠加杠杆抬 ROE
A32: 现金 | B32: 现金转化是否稳定 | C32: 公告确认经营活动净现金流入，但没有金额。现金转化因此待查。特许经营摊销FY2026为1,195.8，折旧与摊销合计在经调整EBITDA桥里为1,919.8，会计利润会低于现金利润，但缺了现金流量表仍不能定量。 | F32: 应计利润高、资本化激进
A33: 资产负债 | B33: 短债覆盖、商誉、应收/存货 | C33: 现金20,760.7覆盖一年内到期债务约79亿。净负债比率从0.37降到0.28。存货只有28.0。贸易应收从1,853.2降到1,659.6。商誉未单列，待查。保险合约负债93,743.5是负债大头。 | F33: 商誉大、应收存货异常升

Sheet 评分
A1: 质量评分 · F / Z / M（体检，不是买卖信号）
A2: ="标的："&IF(封面!B5="","（先填封面）",封面!B5)
A3: 可从「财务」表抄最近两年，或直接填。空着的项不记分。金融、保险、REITs 不要用原版 Z。高增长公司 M 分数易假阳性。
A5: A. 输入（与财务表最近两年对应）
A6: 项目 | B6: 上年 T-1 | C6: 本年 T | D6: 说明 | E6: 财务表对照
A7: 净利润 | B7: 2162 | C7: 2392.6 | D7: 财务!E11 / F11
A8: 总资产 | B8: 172895.6 | C8: 191157.6 | D8: 财务!E17 / F17
A9: 经营现金流 | D9: 财务!E12 / F12
A10: 长期/有息负债 | B10: 34861.8 | C10: 32415.2 | D10: 财务!E18 / F18
A11: 流动资产 | D11: 资产负债表
A12: 流动负债 | D12: 资产负债表
A13: 股本数量 | B13: 4009.8 | C13: 4566.3 | D13: 财务!E24 / F24
A14: 毛利 | B14: 3951.5 | C14: 4019.2 | D14: 财务!E8 / F8
A15: 营业收入 | B15: 24285.3 | C15: 27099.7 | D15: 财务!E7 / F7
A16: 留存收益 | D16: Z 分数用
A17: EBIT / 营业利润 | B17: 3232.6 | C17: 3731.5 | D17: Z 分数用
A18: 总负债 | B18: 133013.9 | C18: 149066.2 | D18: Z / M 用
A19: 股权市值 | C19: 38356.92 | D19: 现价×股本，Z 的 X4
A20: 营运资本 | D20: 留空则用右边自动值 | E20: =IF(C20<>"",C20,IF(OR(C11="",C12=""),"",C11-C12)) | F20: 本年营运资本(用于Z)
A21: 应收账款 | B21: 1853.2 | C21: 1659.6 | D21: M 分数用
A22: 固定资产净额 PPE | B22: 1226.9 | C22: 1156.7 | D22: M 分数用
A23: 折旧 | B23: 310 | C23: 338.1 | D23: M 分数用
A24: 销售管理费用 | B24: 1015.1 | C24: 1134.5 | D24: M 分数用；没有可留空
A26: 一键带入财务表最近两年（可覆盖上面黄格：把下面公式复制到 B7:C15）
A27: 提示 | B27: 不想手工抄：把 B7 改成 =财务!E11，C7 改成 =财务!F11，其余科目同样从财务表 E/F 列引用。改完字体会变绿，这是正常的。
A29: B. Piotroski F-Score（9 项，变好=1）
A30: 代码 | B30: 条件 | C30: 得分 | D30: 计算说明
A31: F1 | B31: ROA > 0 | C31: =IF(OR(C7="",C8="",C8=0),"",IF(C7/C8>0,1,0)) | D31: 本年净利润/总资产>0
A32: F2 | B32: CFO > 0 | C32: =IF(C9="","",IF(C9>0,1,0)) | D32: 经营现金流>0
A33: F3 | B33: ΔROA > 0 | C33: =IF(OR(B7="",B8="",B8=0,C7="",C8="",C8=0),"",IF(C7/C8>B7/B8,1,0)) | D33: ROA 改善
A34: F4 | B34: CFO > 净利润 | C34: =IF(OR(C9="",C7=""),"",IF(C9>C7,1,0)) | D34: 应计为负（现金质量）
A35: F5 | B35: 杠杆下降 | C35: =IF(OR(B10="",B8="",B8=0,C10="",C8="",C8=0),"",IF(C10/C8<B10/B8,1,0)) | D35: 有息负债/资产下降
A36: F6 | B36: 流动比率上升 | C36: =IF(OR(B11="",B12="",B12=0,C11="",C12="",C12=0),"",IF(C11/C12>B11/B12,1,0)) | D36: CA/CL 改善
A37: F7 | B37: 未增发 | C37: =IF(OR(B13="",C13=""),"",IF(C13<=B13,1,0)) | D37: 股本未增加
A38: F8 | B38: 毛利率改善 | C38: =IF(OR(B14="",B15="",B15=0,C14="",C15="",C15=0),"",IF(C14/C15>B14/B15,1,0)) | D38: 毛利/收入上升
A39: F9 | B39: 周转改善 | C39: =IF(OR(B15="",B8="",B8=0,C15="",C8="",C8=0),"",IF(C15/C8>B15/B8,1,0)) | D39: 收入/资产上升
A40: F-Score 合计 | B40: =SUM(C31:C39) | C40: =IF(COUNT(C31:C39)<9,"缺项，仅供参考",IF(B40>=8,"强",IF(B40<=3,"弱","中"))) | D40: 8–9 强；0–3 弱。只看趋势质量，不看贵贱。
A42: C. Altman Z-Score（非金融）
A43: 模型 | B43: 非制造/新兴 | C43: 原版：Z=1.2X1+1.4X2+3.3X3+0.6X4+1.0X5。非制造：6.56X1+3.26X2+6.72X3+1.05X4。
A44: X1 营运资本/总资产 | B44: =IF(OR(E20="",C8="",C8=0),"",E20/C8)
...

Sheet 估值
A1: 护城河与估值 · 给区间，不给神预测
A2: ="标的："&IF(封面!B5="","（先填封面）",封面!B5&" 现价 "&TEXT(封面!B9,"#,##0.00")&封面!B10)
A3: 相对估值看分位和同行；绝对估值用三情景。黄格填假设。隐含价格默认 = 情景EPS × 情景PE，也可直接覆盖「隐含价格」。
A5: A. 护城河（Morningstar 五源，可多选）
A6: 来源 | B6: 有/无/弱 | C6: 证据（财务或业务）
A7: 无形资产（品牌/专利/牌照） | B7: 有 | C7: 收费公路特许经营、保险牌照和会展场馆是牌照与资产，不是可无限复制的品牌溢价。毛利率FY2026为0.148。 | E7: 溢价能否维持、续期/诉讼
A8: 转换成本 | B8: 弱 | C8: 道路有区位，保险有续保惯性，但物流出租率和建造合约都可以换对手。没有可靠的全集团续约率。 | E8: 续约率、churn、客户集中度
A9: 网络效应 | B9: 无 | C9: 道路、建造和物流不是双边网络。保险分销在扩大，但还不是网络效应。 | E9: 双边增长是否还在加速
A10: 成本优势 | B10: 弱 | C10: 平均借贷成本约4.1%，与上年相同。毛利率下降，没有扩大的成本优势。 | E10: 单位成本 vs 同行、产能利用率
A11: 有效规模（利基） | B11: 有 | C11: 区域收费公路和香港建造合约是有效规模，新进入者要先拿到特许经营或政府合约。 | E11: 新进入者是否长期亏钱
A12: 定量锚 | B12: 近似ROIC 0.057。再投资去向是物流物业和数据中心权益，不是已证实的高回报扩产。是否高于WACC待查。
A14: B. 相对估值
A15: 倍数 | B15: 当前 | C15: 自身 5 年中位 | D15: 同行中位 | E15: 分位含义 | F15: 更适合
A16: PE | B16: 15.849057 | E16: =IF(OR(B16="",C16=""),"",IF(B16>C16,"高于自身中位","不高于自身中位")) | F16: 成长股、盈利稳定
A17: PB | B17: 0.96573627 | E17: =IF(OR(B17="",C17=""),"",IF(B17>C17,"高于自身中位","不高于自身中位")) | F17: 银行、周期、重资产
A18: PEG | E18: =IF(OR(B18="",C18=""),"",IF(B18>C18,"高于自身中位","不高于自身中位")) | F18: 高增长
A19: EV/EBITDA | E19: =IF(OR(B19="",C19=""),"",IF(B19>C19,"高于自身中位","不高于自身中位")) | F19: 资本密集、杠杆不同的同行
A20: EV/Sales | E20: =IF(OR(B20="",C20=""),"",IF(B20>C20,"高于自身中位","不高于自身中位")) | F20: 尚未稳定盈利
A21: FCF Yield | E21: =IF(OR(B21="",C21=""),"",IF(B21>C21,"高于自身中位","不高于自身中位")) | F21: 自由现金流可见的公司
A23: C. 三情景（绝对/相对混合）
A24: 情景 | B24: 概率 | C24: EPS 或 FCF/股 | D24: 倍数 PE/EV | E24: 隐含价格 | F24: 距现价
A25: Bear | B25: 0.25 | C25: 0.45 | D25: 10 | E25: =IF(OR(C25="",D25=""),"",C25*D25) | F25: =IF(OR(E25="",封面!B9="",封面!B9=0),"",E25/封面!B9-1)
A26: Base | B26: 0.5 | C26: 0.53 | D26: 12 | E26: =IF(OR(C26="",D26=""),"",C26*D26) | F26: =IF(OR(E26="",封面!B9="",封面!B9=0),"",E26/封面!B9-1)
A27: Bull | B27: 0.25 | C27: 0.62 | D27: 14 | E27: =IF(OR(C27="",D27=""),"",C27*D27) | F27: =IF(OR(E27="",封面!B9="",封面!B9=0),"",E27/封面!B9-1)
A28: Base 隐含价 | B28: =E26 | C28: =E26 | D28: 封面读取 C28
A29: 概率加权价 | B29: =IF(ABS(SUM(B25:B27)-1)>0.02,"请检查概率合计=100%",IF(COUNT(E25:E27)<3,"",SUMPRODUCT(B25:B27,E25:E27))) | C29: =B29
A30: 期望价 vs 现价 | B30: =IF(OR(B29="",封面!B9="",封面!B9=0),"",B29/封面!B9-1) | C30: =B30
A31: 估值区间文本 | B31: =IF(COUNT(E25:E27)<3,"未完成",TEXT(MIN(E25:E27),"#,##0.00")&" ~ "&TEXT(MAX(E25:E27),"#,##0.00")&" "&封面!B10) | C31: =B31 | D31: 封面读取 C31。可把 E 列改成你的 DCF 价格（直接覆盖公式）。
A33: D. 市场共识 vs 我的分歧
A34: 项目 | B34: 市场隐含 / 一致预期 | C34: 我的预期 | D34: 历史分位 / base rate | E34: 净预期差 | F34: 来源
A35: 明年收入增速 | B35: 公司没有给出FY2027收入指引。雅虎forwardEps为0.6812，抓取时价格8.40，未经公告核对。 | C35: 基准假设EPS维持0.53港元，不把雅虎0.68写成我的预测。 | D35: 自身五年市盈率中位数待查。 | E35: 我的基准低于数据商的远期每股盈利。 | F35: 业绩公告；雅虎，2026-09-25。
A36: 利润率 | B36: 市场用6.53%的上涨交易已公布的11%利润增长。 | C36: 毛利率0.148，不假设扩张。金融板块应占经营溢利增19%，物流降13%。 | D36: FY2026经营溢利率3,731.5/27,099.7=0.138。 | E36: 分歧在增长能维持多久，不在已经公布的FY2026。 | F36: 业绩公告综合收益表。
A37: FCF / 派息 | B37: 收盘8.40对应普通股息0.61的收益率0.073。市场没有公布自由现金流假设。 | C37: 普通股息总额2,785.4，除以股东应占溢利2,392.6，派息比例1.16。自由现金流待查。 | D37: FY2025普通股息总额含特别股息，公告写明与0.61不直接可比。 | E37: 现金覆盖是未核对项，不是已证实的安全边际。 | F37: 业绩公告股息附注。
A38: 竞争格局 | B38: 业绩日上涨，恒指当天跌1.01%。 | C38: 金融已是最大应占经营溢利来源，道路持平，物流和建筑走弱。 | D38: 多元化集团，不是单一保险或单一公路。 | E38: 不把板块轮动写成新的增长。 | F38: 业绩公告分部；收盘复盘2026-09-25。
A39: 倍数/折现率 | B39: 现价对应FY2026基本每股盈利0.53的市盈率15.85。 | C39: 基准0.53×12=6.36港元。 | D39: 五年中位数和同行中位数待查，不填假的同行中位。 | E39: 现价8.40高于基准6.36，接近牛市8.68。概率加权6.47。 | F39: 情景为假设。市盈率用公告基本每股盈利。
A41: 非金融深 DCF 可用 Damodaran fcffsimpleginzu.xlsx；金融用 divginzu.xlsx。本表只要求三情景价格，不强制完整 DCF。

Sheet 情绪
A1: 情绪与预期差 · 读预期，不追热度
A2: ="标的："&IF(封面!B5="","（先填封面）",封面!B5)
A3: 目标：当前价格计入了什么故事、谁在交易、拥挤后谁是对手盘。基本面好+情绪过热 → 等或减小仓。基本面差+情绪冰点 ≠ 自动买点。
A5: 四层情绪
A6: 层 | B6: 现在的样子（填写） | C6: 拥挤度 热/中/冷 | D6: 拥挤时 | E6: 冷清时 | F6: 数据来源
A7: 新闻叙事 | B7: 9月25日是FY2026业绩的第一个交易日。复盘写收盘涨6.53%至8.40港元，成交1.17亿港元。叙事是利润增11%和末期息0.33港元。 | C7: 中 | D7: 标题同质、只有一个故事 | E7: 几乎没人写，或只剩例行公告 | F7: output/review/2026-09-25/review.md；港交所业绩公告。
A8: 社交与散户 | B8: 社交提及量待查。当天成交额1.17亿港元，高于此前多数交易日。 | C8: 中 | D8: 提及暴增且一边倒看多 | E8: 提及低、争议少、换手低 | F8: 雅虎日线2026-09-25成交量13,943,709股，乘收盘8.40港元。
A9: 卖方与资金 | B9: 没有公司给出的FY2027一致预期口径。雅虎forwardEps 0.6812只作数据商数字。 | C9: 冷 | D9: 一致预期很高、上调扎堆 | E9: 覆盖少、目标价低于现价、机构在减 | F9: 雅虎，抓取日2026-09-25。
A10: 期权与波动 | B10: 港股无期权可用。20日日均成交额见风险表。业绩日放量，不是连续涨停。 | C10: 中 | D10: IV 极高、看涨期权拥挤 | E10: IV 处于自身低位；A 股用换手代替 | F10: 雅虎日线2026-08-28至2026-09-25。
A12: 检查项
A13: # | B13: 检查项 | C13: 结论 | D13: 记录
A14: 1 | B14: 过去 30 天核心新闻已读，并能用一句话概括市场叙事 | C14: 是 | D14: 市场叙事是业绩增长和现金股息。复盘同时提醒不要把新十送一当成已经成立的方案。
A15: 2 | B15: 查过一致预期 EPS / 目标价，并标出我和共识的分歧点 | C15: 是 | D15: 公司无FY2027每股盈利指引。我的基准EPS是0.53，低于雅虎forwardEps 0.68。
A16: 3 | B16: 看过提及量或换手：热门拥挤还是乏人问津 | C16: 是 | D16: 用成交额不用社交提及量。提及量待查。20日涨幅未过20%，当天相对放量。
A17: 4 | B17: 看过机构/北向/融资或 13F 的方向，而不是单日资金颜色 | C17: 待查 | D17: 9月25日港股通暂停，没有南向。更长的持仓方向没有可靠序列，不用单日成交代替。
A18: 5 | B18: 美股看 IV Rank、Put/Call；A 股用换手+涨跌停情绪代替 | C18: 是 | D18: 港股用成交额。业绩日成交额远高于20日中位数，但仍是一日事件。
A19: 6 | B19: 写清楚：市场已经定价了什么，我额外押的是什么 | C19: 是 | D19: 已定价的是FY2026利润增长和0.61港元普通股息。我没有在8.40港元上额外押FY2027增长。
A20: 市场已定价 | B20: FY2026股东应占溢利增11%、末期息0.33港元，以及一个交易日6.53%的涨幅。
A22: 我额外押的 | B22: 没有额外的多头。若价格回到基准6.36港元附近，且现金流量表证明经营现金流覆盖普通股息，才重新讨论。

Sheet 风险
A1: 风险与仓位 · 先写证伪，再定量
A2: ="标的："&IF(封面!B5="","（先填封面）",封面!B5&" 现价 "&TEXT(封面!B9,"#,##0.00"))
A3: 只保留会推翻论点的风险。仓位由波动和流动性决定，不由「有多看好」决定。保守账户单票风险预算常见 0.25%–1% 组合权益。
A5: A. 仓位计算器
A6: 组合权益 | B6: 1000000 | C6: 你的可投资本金
A7: 单票风险预算 | B7: 0.005 | C7: 亏到证伪时，最多亏组合的多少
A8: 证伪跌幅 | B8: 0.3 | C8: 从现价到无效化的跌幅（正数）
A9: 日均成交额 | B9: 13505549 | C9: 与现价同一货币
A10: 流动性占用上限 | B10: 0.05 | C10: 不超过日均成交的比例
A12: 风险预算金额 | B12: =IF(OR(B6="",B7=""),"",B6*B7) | C12: 权益 × 风险预算
A13: 波动反推仓位金额 | B13: =IF(OR(B12="",B8="",B8=0),"",B12/B8) | C13: 风险预算金额 / 证伪跌幅
A14: 流动性上限金额 | B14: =IF(OR(B9="",B10=""),"",B9*B10) | C14: 日均成交 × 占用上限
A15: 建议金额 | B15: =IF(B13="",IF(B14="","",B14),IF(B14="",B13,MIN(B13,B14))) | C15: =B15 | D15: 封面读 C15
A16: 建议仓位上限 | B16: =IF(OR(B15="",B6="",B6=0),"",B15/B6) | C16: =B16 | D16: 封面读 C16
A17: 建议股数 | B17: =IF(OR(B15="",封面!B9="",封面!B9=0),"",B15/封面!B9)
A19: B. Pre-mortem（假设一年后失败）
A20: # | B20: 失败原因（至少一条打论点） | C20: 当前证据 | D20: 监控指标 | E20: 触发后动作 | F20: 强度 高/中/低
A21: 1 | B21: 普通股息2,785.4百万港元高于股东应占溢利2,392.6百万港元，现金覆盖不足。 | C21: 派息比例1.16。公告只说经营现金为净流入，没有金额。 | D21: 年报现金流量表的经营现金流，以及FY2027中期是否维持每股股息金额。 | E21: 若经营现金流低于普通股息，等待改为不做。 | F21: 高
A22: 2 | B22: 新的十送一若在11月17日通过，每股盈利和股价会按股数摊薄，总价值不变。 | C22: 公告建议2026-11-23名册股东每十股获发一股红股，须股东会和上市批准。 | D22: 11月17日股东周年大会决议。 | E22: 不把红股当成基本面利好。通过后用新的股数重算每股价值。 | F22: 中
A23: 3 | B23: 金融板块成为最大利润来源后，保险投资和退保会主导利润波动。 | C23: 金融应占经营溢利1,474.7，占4,590.6的0.32。偿付能力充足率285%。 | D23: 周大福人寿偿付能力、新业务价值、内含价值。 | E23: 偿付能力明显下滑则降低质量评级。 | F23: 中
A25: C. 交易预案
A26: 持有期 | B26: 6至12个月，看到FY2027中期业绩。 | E26: 例如 6–18 个月，事件驱动写到催化剂日
A27: 建仓区间 | B27: 不在8.40港元建仓。重新讨论的价格在基准6.36港元或以下，且经营现金流已经披露并覆盖股息。 | E27: 价格或估值分位，不要写「看着办」
A28: 无效化 / 证伪 | B28: FY2027股东应占溢利同比下降超过15%，或净负债比率重新高于0.37，或取消普通股息。价格补充是从8.40下跌0.30。 | E28: 基本面事件优先；价格止损只作补充
A29: 减仓 / 退出 | B29: 现价不买。若持有，股息削减或负债率回升时减。 | E29: 论点兑现、估值到目标、或证伪触发
A30: 下次复盘日 | B30: 2026-11-17股东周年大会；其后是FY2027中期业绩。 | E30: 下次财报或某个领先指标阈值
A31: 与现有持仓重叠 | B31: 与香港综合企业、内房链的建造合约和保险股重叠。数据中心权益还小，不按算力主题加仓。 | E31: 行业 / 因子 / 单一客户
A33: D. 风险地图（只填会改变动作的）
A34: 类型 | B34: 是否相关 | C34: 具体内容 | D34: 监控指标 | E34: 仓位含义 | F34: 状态
A35: 经营 | B35: 是 | C35: 道路流量可比口径约降1%，物流应占经营溢利降13%，建筑降4%。金融增19%抵消了这些。 | D35: 销量/ASP、毛利率、份额 | E35: 论点伤了就减或清 | F35: 观察
A36: 财务 | B36: 是 | C36: 净负债比率0.28，但一年内到期债务仍约79亿，派息比例高于1。 | D36: 净负债、利息覆盖、FCF | E36: 杠杆高则硬性缩小仓 | F36: 观察
A37: 估值 | B37: 是 | C37: 8.40高于基准6.36。贵，所以公式给出的仓位只是上限。 | D37: PE 分位、久期、WACC | E37: 贵的时候少配 | F37: 观察
A38: 市场 | B38: 是 | C38: 要闻写10年期美债上行至5.20%附近，复盘不把互相冲突的收益率合成一个收盘点。利率高时，股息股仍要看现金是否真能支付。 | D38: Beta、波动、最大回撤 | E38: 按波动倒数仓位 | F38: 观察
A39: 流动性 | B39: 否 | C39: 20日日均成交额13505549港元，中位数7040156。流动性不约束这个研究仓。 | D39: 日均成交、价差 | E39: 限制绝对金额 | F39: 观察
A40: 治理/政策 | B40: 是 | C40: 建议中的红股和已转换的可换股债券改变每股数字。0.75%可交换债券以公允价值入账，计入后净负债比率为0.33。 | D40: 增发、关联交易、监管 | E40: 一票否决或观察仓 | F40: 观察

Sheet 备忘录
A1: 个股备忘录 · 写完就能存档
A2: ="【"&IF(封面!B5="","代码未填",封面!B5)&"】 "&封面!B6&" | "&封面!B7&" | "&TEXT(封面!B8,"YYYY-MM-DD")&" | 动作："&封面!B19
A3: 结构：执行摘要 → 公司 → 行业 → 财务 → 估值 → 情绪 → 催化剂 → 风险 → 动作。把黄格里的提示换成事实和来源。打印本表即可作为研究报告。
A5: ="论点："&封面!B13
A7: 0. 执行摘要
A8: ① 内在价值：贵。概率加权价6.47港元，比现价8.40低22.9%。② 近月方向：中性。业绩日上涨，恒指下跌，不是连板。③ 动作：等待，不在8.40建仓。区间：4.50 ~ 8.68 HKD。最大风险：普通股息相对股东应占溢利的派息比例为1.16，经营现金流金额仍待查。云端无 Excel，汇总按模板公式计算。 F=4（缺项，仅供参考，6/9），Z=缺项，M=-2.93（未触发阈值；缺AQI/TATA，公式按0计入）。仓位上限1.67%，对应假设组合100万港元里的16667港元。
A10: 1. 公司与商业模式
A11: 周大福创建（CTF Services，00659）经营收费公路、人寿保险、物流、建筑和设施管理。FY2026对外收入27,099.7百万港元（建筑17,915.8、金融4,752.4、道路2,777.8、设施1,509.5、物流144.2）。股东应占溢利2,392.6，基本每股盈利0.53，摊薄0.52。加权平均股数4,498.4百万股。期末股本4,566.3百万股。主席郑家纯。近12个月的大事是2025年12月已派发的十送一、2.8%可换股债券转股，以及9月24日的全年业绩。来源：港交所2026-09-24业绩公告。
A13: 2. 行业与竞争
A14: 周期位置是业绩公布日，不是行业景气总开关。当日要闻的两条主线是甲骨文Project Jupiter不可抗力和埃斯孔迪达复产评估，都没有点名这家公司，不能写成订单。要闻写A股9月25日起休市；复盘写港股通暂停，恒指收24510.09、跌1.01%，全日成交1,022.03亿港元。应占经营溢利：金融1,474.7（+19%）、道路1,442.8（持平）、建筑688.9（-4%）、物流645.0（-13%）、策略性投资251.4、设施87.8。同行中位数待查，不填。资本成本的背景是公告里的平均借贷成本约4.1%，以及要闻里长端美债处于2007年以来高位附近。
A16: 3. 财务质量
A17: 只有FY2025和FY2026两列来自同一份公告，更早年度待查，避免把对不上的数据库旧数混进来。收入24285.3到27099.7。毛利率0.163到0.148，口径是收入减销售成本减保险服务费用。股东应占溢利2162.0到2392.6。经营现金流金额待查，方向为净流入。期末ROE 0.060。近似ROIC 0.057。现金转化待查。保险合约负债93,743.5，所以原版制造业Z和流动比率都不适用，评分表改用非制造模型，但流动资产、流动负债和留存收益仍缺，Z为缺项。可信度B：利润、资产和股息与经审核业绩公告核对过，现金流量表不在这份公告里。
A19: 4. 估值
A20: 相对：现价8.40除以基本每股盈利0.53，市盈率15.85；市值38356.9百万港元除以股东权益39717.8，市净率0.97。五年中位数和同行中位数待查。绝对：熊市每股盈利0.45×10倍=4.50（概率0.25）；基准0.53×12倍=6.36（概率0.50）；牛市0.62×14倍=8.68（概率0.25）。概率合计1。概率加权6.47，相对现价-22.9%。这些每股盈利和倍数是假设。红股若通过，总股权价值不变，每股数字要除以1.1，不把送股写成上涨空间。
A22: 5. 情绪与预期差
A23: 叙事一句：全年业绩增长和现金股息。拥挤度中。一致预期没有公司口径。市场已定价FY2026的11%利润增长。我额外押的是空的：8.40不交易。复盘把公告里的十送一读成2025年12月已发行、只用于调整股息比较基数。公告「末期股息及派发红股」一节同时建议向2026年11月23日名册股东按每十股现有股份获发一股红股，须11月17日股东会通过。本备忘录以公告正文为准，并写明复盘的不同读法。要闻没有点名这只股票。
... A34: 声明：本研究记录仅供个人决策备忘，不构成投资建议。

Sheet 工具
A1: 工具对照 · 取数与模型，不是第二套流程
A2: 能免费走通：年报原文 + akshare 或 yfinance + 本模板 +（可选）Damodaran 表。不要同时开五套 AI 选股工具。
A4: 取数
A5: 工具 | B5: 市场 | C5: 费用 | D5: 擅长 | E5: 链接
A6: AKShare | B6: A/H 为主 | C6: 免费 | D6: 行情、财务、资金、宏观；接口偶有变动 | E6: github.com/akfamily/akshare
A7: Tushare Pro | B7: A 股 | C7: 注册额度 | D7: 财务/行情较稳，积分限制部分接口 | E7: tushare.pro
A8: yfinance / SEC EDGAR | B8: 美股 | C8: 免费 | D8: 价格与 10-K/10-Q 原文 | E8: sec.gov
A9: 东方财富 / 理杏仁 | B9: A/H | C9: 免费/付费 | D9: 一致预期、估值、资金
A10: 公司年报 / 港交所披露易 | B10: A/H | C10: 免费 | D10: 最终事实来源，关键数字必须对到此处
A12: 估值与质量
A13: 资源 | B13: 用途
A14: Damodaran ginzu 表 | B14: 非金融 FCFF：pages.stern.nyu.edu/~adamodar/pc/fcffsimpleginzu.xlsx ；金融 DDM：divginzu.xlsx
A15: 本模板评分表 | B15: Piotroski F、Altman Z、Beneish M 快速体检
A16: investTemplate | B16: A/H 价值股、高股息、烟蒂、央国企深度体检（GitHub: sunheyi6/investTemplate）
A18: 最低可行工具链
A19: · A 股：年报 PDF + 本模板 + 东方财富一致预期。深度价值再上 investTemplate。
A20: · 港股：年报 / 披露易 + 本模板。代码用 0992.HK 这种 Yahoo 形式便于对照行情。
A21: · 美股：10-K + 本模板 +（可选）Damodaran + 期权 IV。
A22: · 本模板不代替年报。黄格里的每一个关键数字都应该能指回一页财报或一份公告。
